const New = require("../models/new.model");

exports.Create = async (req, res) => {
    try {

    } catch (error){
        console.log("error", error);
        const errorMessage = error?.message;
        return res.status(500).json({
            error: errorMessage,
            message: "Une erreur interne est survenue, veuillez réessayer plus tard."
        })
    }
}

exports.GetAll = async (req, res) => {
    try {
 
    } catch (error){
        console.log("error");
        return res.status(500).json({
            error: true,
            message: "Une erreur interne est survenue, veuillez réessayer plus tard."
        })
    }
}

exports.GetById = async (req, res) => {
    try {
 
    } catch (error){
        console.log("error");
        return res.status(500).json({
            error: true,
            message: "Une erreur interne est survenue, veuillez réessayer plus tard."
        })
    }
}

exports.Update = async (req, res) => {
    try {
       
    } catch (error){
        console.log("error");
        return res.status(500).json({
            error: true,
            message: "Une erreur interne est survenue, veuillez réessayer plus tard."
        })
    }
}

exports.Delete = async (req, res) => {
    try {
        
        
    } catch (error){
        console.log("error");
        return res.status(500).json({
            error: true,
            message: "Une erreur interne est survenue, veuillez réessayer plus tard."
        })
    }
}