const New = require("../models/new.model");

exports.Create = async (req, res) => {
    try {

        const { title, content } = req.body;

        const { id: categorieId } = req.decoded;

        const thumbnail = req.file.filename;

        if (!title || !thumbnail || !content || !categorieId) {
            return res.status(400).json({
                error: true,
                message: "Requête invalide."
            });
        }

        await new New({
            title: title,
            thumbnail: thumbnail,
            content: content,
            categorieId: categorieId
        }).save();

        return res.status(201).json({
            error: false,
            message: "L'actualité a bien été créée."
        });

    } catch (error) {
        console.log(error);
        return res.status(500).json({
            error: true,
            message: "Une erreur interne est survenue, veuillez réessayer plus tard."
        })
    }
}

exports.GetAll = async (req, res) => {
    try {
        const news = await New.findAll();

        return res.status(200).json({
            error: false,
            message: "Les actualités ont bien été récupérés",
            data: news
        })
    } catch (error) {
        console.log("error");
        return res.status(500).json({
            error: true,
            message: "Une erreur interne est survenue, veuillez réessayer plus tard."
        })
    }
}

exports.GetById = async (req, res) => {
    try {

    } catch (error) {
        console.log("error");
        return res.status(500).json({
            error: true,
            message: "Une erreur interne est survenue, veuillez réessayer plus tard."
        })
    }
}

exports.Update = async (req, res) => {
    try {

    } catch (error) {
        console.log("error");
        return res.status(500).json({
            error: true,
            message: "Une erreur interne est survenue, veuillez réessayer plus tard."
        })
    }
}

exports.Delete = async (req, res) => {
    try {


    } catch (error) {
        console.log("error");
        return res.status(500).json({
            error: true,
            message: "Une erreur interne est survenue, veuillez réessayer plus tard."
        })
    }
}